<?xml version="1.0" encoding="utf-8"?>
<!-- This URDF was automatically created by SolidWorks to URDF Exporter! Originally created by Stephen Brawner (brawner@gmail.com) 
     Commit Version: 1.6.0-4-g7f85cfe  Build Version: 1.6.7995.38578
     For more information, please see http://wiki.ros.org/sw_urdf_exporter -->
<robot
  name="balance">
  <link
    name="base_link">
    <inertial>
      <origin
        xyz="0.008 0 0.141"
        rpy="0 0 0" />
      <mass
        value="16.932" />
      <inertia
        ixx="0.37275"
        ixy="-0.00121"
        ixz="-0.06794"
        iyy="0.47986"
        iyz="0.025803"
        izz="0.46278" />
    </inertial>
    <visual>
      <origin
        xyz="0 0 0"
        rpy="0 0 0" />
      <geometry>
        <mesh
          filename="../meshes/base_link.STL" />
      </geometry>
      <material
        name="">
        <color
          rgba="0.75294 0.75294 0.75294 1" />
      </material>
    </visual>
    <collision>
      <origin
        xyz="0 0 0"
        rpy="0 0 0" />
      <geometry>
        <mesh
          filename="../meshes/base_link.STL" />
      </geometry>
    </collision>
  </link>
  <link
    name="lf0_link">
    <inertial>
      <origin
        xyz="-0.065851 -0.00030353 -0.0092889"
        rpy="0 0 0" />
      <mass
        value="0.94321" />
      <inertia
        ixx="0.00050936"
        ixy="-3.8772E-05"
        ixz="2.8159E-06"
        iyy="0.0023776"
        iyz="5.2676E-07"
        izz="0.0028506" />
    </inertial>
    <visual>
      <origin
        xyz="0 0 0"
        rpy="0 0 0" />
      <geometry>
        <mesh
          filename="../meshes/lf0_link.STL" />
      </geometry>
      <material
        name="">
        <color
          rgba="0.75294 0.75294 0.75294 1" />
      </material>
    </visual>
    <collision>
      <origin
        xyz="0 0 0"
        rpy="0 0 0" />
      <geometry>
        <mesh
          filename="../meshes/lf0_link.STL" />
      </geometry>
    </collision>
  </link>
  <joint
    name="lf0_joint"
    type="revolute">
    <origin
      xyz="-0.00058256 0.14902 -0.0093063"
      rpy="-1.5708 0 0" />
    <parent
      link="base_link" />
    <child
      link="lf0_link" />
    <axis
      xyz="0 0 1" />
    <limit
      lower="-1.1"
      upper="0.4"
      effort="40"
      velocity="10.472" />
  </joint>
  <link
    name="lf1_link">
    <inertial>
      <origin
        xyz="-0.0092352 0.1524 0.0042684"
        rpy="0 0 0" />
      <mass
        value="0.61081" />
      <inertia
        ixx="0.006558"
        ixy="-0.000191"
        ixz="9E-06"
        iyy="0.00026"
        iyz="-0.000328"
        izz="0.006647" />
    </inertial>
    <visual>
      <origin
        xyz="0 0 0"
        rpy="0 0 0" />
      <geometry>
        <mesh
          filename="../meshes/lf1_link.STL" />
      </geometry>
      <material
        name="">
        <color
          rgba="0.75294 0.75294 0.75294 1" />
      </material>
    </visual>
    <collision>
      <origin
        xyz="0 0 0"
        rpy="0 0 0" />
      <geometry>
        <mesh
          filename="../meshes/lf1_link.STL" />
      </geometry>
    </collision>
  </link>
  <joint
    name="lf1_joint"
    type="revolute">
    <origin
      xyz="-0.215 0 0.01715"
      rpy="0 0 0" />
    <parent
      link="lf0_link" />
    <child
      link="lf1_link" />
    <axis
      xyz="0 0 1" />
    <limit
      lower="-0.98"
      upper="0.366"
      effort="40"
      velocity="6" />
  </joint>
  <link
    name="lwheel_link">
    <inertial>
      <origin
        xyz="5.5511E-17 -2.7756E-17 -0.0012723"
        rpy="0 0 0" />
      <mass
        value="0.17502" />
      <inertia
        ixx="0.00040689"
        ixy="-4.9591E-21"
        ixz="-1.4812E-18"
        iyy="0.00040689"
        iyz="7.2176E-20"
        izz="0.00178918" />
    </inertial>
    <visual>
      <origin
        xyz="0 0 0"
        rpy="0 0 0" />
      <geometry>
        <mesh
          filename="../meshes/lwheel_link.STL" />
      </geometry>
      <material
        name="">
        <color
          rgba="0.89804 0.91765 0.92941 1" />
      </material>
    </visual>
    <collision>
      <origin
        xyz="0 0 0"
        rpy="0 0 0" />
      <geometry>
        <mesh
          filename="../meshes/lwheel_link.STL" />
      </geometry>
    </collision>
  </link>
  <joint
    name="lwheel_joint"
    type="revolute">
    <origin
      xyz="0.012 0.25772 0.02455"
      rpy="0 0 0" />
    <parent
      link="lf1_link" />
    <child
      link="lwheel_link" />
    <axis
      xyz="0 0 1" />
    <limit
      effort="3.5"
      velocity="59.795" />
  </joint>
  <link
    name="rf0_link">
    <inertial>
      <origin
        xyz="0 0 0"
        rpy="0 0 0" />
      <mass
        value="0" />
      <inertia
        ixx="0"
        ixy="0"
        ixz="0"
        iyy="0"
        iyz="0"
        izz="0" />
    </inertial>
    <visual>
      <origin
        xyz="0 0 0"
        rpy="0 0 0" />
      <geometry>
        <mesh
          filename="../meshes/rf0_link.STL" />
      </geometry>
      <material
        name="">
        <color
          rgba="1 1 1 1" />
      </material>
    </visual>
    <collision>
      <origin
        xyz="0 0 0"
        rpy="0 0 0" />
      <geometry>
        <mesh
          filename="../meshes/rf0_link.STL" />
      </geometry>
    </collision>
  </link>
  <joint
    name="rf0_joint"
    type="revolute">
    <origin
      xyz="-0.00058256 -0.17889 -0.0093063"
      rpy="1.5708 0 0" />
    <parent
      link="base_link" />
    <child
      link="rf0_link" />
    <axis
      xyz="0 0 1" />
    <limit
      lower="-0.4"
      upper="1.1"
      effort="40"
      velocity="10.472" />
  </joint>
  <link
    name="rf1_link">
    <inertial>
      <origin
        xyz="0.0092352 -0.15237 0.004267"
        rpy="0 0 0" />
      <mass
        value="0.6108" />
      <inertia
        ixx="0.006562"
        ixy="0.00010808"
        ixz="-4.3004E-08"
        iyy="0.00026"
        iyz="-2.3777E-07"
        izz="0.006651" />
    </inertial>
    <visual>
      <origin
        xyz="0 0 0"
        rpy="0 0 0" />
      <geometry>
        <mesh
          filename="../meshes/rf1_link.STL" />
      </geometry>
      <material
        name="">
        <color
          rgba="0.75294 0.75294 0.75294 1" />
      </material>
    </visual>
    <collision>
      <origin
        xyz="0 0 0"
        rpy="0 0 0" />
      <geometry>
        <mesh
          filename="../meshes/rf1_link.STL" />
      </geometry>
    </collision>
  </link>
  <joint
    name="rf1_joint"
    type="revolute">
    <origin
      xyz="-0.215 0 0.01715"
      rpy="0 0 0" />
    <parent
      link="rf0_link" />
    <child
      link="rf1_link" />
    <axis
      xyz="0 0 1" />
    <limit
      lower="-0.366"
      upper="0.98"
      effort="40"
      velocity="6" />
  </joint>
  <link
    name="rwheel_link">
    <inertial>
      <origin
        xyz="2.7756E-17 0 -0.0012723"
        rpy="0 0 0" />
      <mass
        value="0.17502" />
      <inertia
        ixx="0.00040689"
        ixy="4.08E-20"
        ixz="8.1869E-20"
        iyy="0.00040689"
        iyz="9.0483E-20"
        izz="0.00178918" />
    </inertial>
    <visual>
      <origin
        xyz="0 0 0"
        rpy="0 0 0" />
      <geometry>
        <mesh
          filename="../meshes/rwheel_link.STL" />
      </geometry>
      <material
        name="">
        <color
          rgba="0.89804 0.91765 0.92941 1" />
      </material>
    </visual>
    <collision>
      <origin
        xyz="0 0 0"
        rpy="0 0 0" />
      <geometry>
        <mesh
          filename="../meshes/rwheel_link.STL" />
      </geometry>
    </collision>
  </link>
  <joint
    name="rwheel_joint"
    type="revolute">
    <origin
      xyz="0.012 -0.25772 0.02455"
      rpy="0 0 0" />
    <parent
      link="rf1_link" />
    <child
      link="rwheel_link" />
    <axis
      xyz="0 0 1" />
    <limit
      effort="3.5"
      velocity="59.795" />
  </joint>
</robot>